The following program will return an error because foo is
inside of a block, and hence cannot be called outside of this
scope.